Intial State:   os.statvfs_result(f_bsize=4096, f_frsize=4096, f_blocks=16, f_bfree=12, 
                f_bavail=12, f_files=4, f_ffree=3, f_favail=3, f_flag=4102, f_namemax=252)
Traceback (most recent call last):
  File "/h/u2/csc369h/fall/pub/a1b-testing/submission.py", line 143, in _run
    self.unmount(abort=timeout_exc is not None, cwd=unmount_cwd)
  File "/h/u2/csc369h/fall/pub/a1b-testing/submission.py", line 116, in unmount
    wait_or_kill(self.a1fs_proc, check=check, timeout=10,
  File "/h/u2/csc369h/fall/pub/a1b-testing/util.py", line 66, in wait_or_kill
    raise exception_chain(subprocess.CalledProcessError(ret, proc.args,
subprocess.CalledProcessError: Command '['./a1fs', '_img_', '/tmp/_reidtest_', '-f', '-d']' died with <Signals.SIGSEGV: 11>.

The above exception was the direct cause of the following exception:

Traceback (most recent call last):
  File "/h/u2/csc369h/fall/pub/a1b-testing/test.py", line 25, in run_test
    test_function(submission, log)
  File "/h/u2/csc369h/fall/pub/a1b-testing/tests.py", line 240, in test
    s.run(fn1, timeout=5)
  File "/h/u2/csc369h/fall/pub/a1b-testing/submission.py", line 207, in run
    return self._run(timeout, cwd, fn, *args, **kwargs)
  File "/h/u2/csc369h/fall/pub/a1b-testing/submission.py", line 148, in _run
    raise exception_chain(fn_exc, a1fs_exc, timeout_exc)
  File "/h/u2/csc369h/fall/pub/a1b-testing/submission.py", line 136, in _run
    return future.result(timeout)
  File "/local/packages/python-3.8/lib/python3.8/concurrent/futures/_base.py", line 439, in result
    return self.__get_result()
  File "/local/packages/python-3.8/lib/python3.8/concurrent/futures/_base.py", line 388, in __get_result
    raise self._exception
  File "/local/packages/python-3.8/lib/python3.8/concurrent/futures/thread.py", line 57, in run
    result = self.fn(*self.args, **self.kwargs)
  File "/h/u2/csc369h/fall/pub/a1b-testing/tests.py", line 239, in fn1
    os.mkdir('dog')
ConnectionAbortedError: [Errno 103] Software caused connection abort: 'dog'

